Traceback (most recent call last):
  File "/home/runner/work/docs.open223.info/docs.open223.info/.venv/lib/python3.12/site-packages/jupyter_core/utils/__init__.py", line 154, in wrapped
    asyncio.get_running_loop()
RuntimeError: no running event loop

During handling of the above exception, another exception occurred:

Traceback (most recent call last):
  File "/home/runner/work/docs.open223.info/docs.open223.info/.venv/lib/python3.12/site-packages/jupyter_cache/executors/utils.py", line 58, in single_nb_execution
    executenb(
  File "/home/runner/work/docs.open223.info/docs.open223.info/.venv/lib/python3.12/site-packages/nbclient/client.py", line 1319, in execute
    return NotebookClient(nb=nb, resources=resources, km=km, **kwargs).execute()
           ^^^^^^^^^^^^^^^^^^^^^^^^^^^^^^^^^^^^^^^^^^^^^^^^^^^^^^^^^^^^^^^^^^^^^
  File "/home/runner/work/docs.open223.info/docs.open223.info/.venv/lib/python3.12/site-packages/jupyter_core/utils/__init__.py", line 158, in wrapped
    return loop.run_until_complete(inner)
           ^^^^^^^^^^^^^^^^^^^^^^^^^^^^^^
  File "/usr/lib/python3.12/asyncio/base_events.py", line 687, in run_until_complete
    return future.result()
           ^^^^^^^^^^^^^^^
  File "/home/runner/work/docs.open223.info/docs.open223.info/.venv/lib/python3.12/site-packages/nbclient/client.py", line 709, in async_execute
    await self.async_execute_cell(
  File "/home/runner/work/docs.open223.info/docs.open223.info/.venv/lib/python3.12/site-packages/nbclient/client.py", line 1005, in async_execute_cell
    exec_reply = await self.task_poll_for_reply
                 ^^^^^^^^^^^^^^^^^^^^^^^^^^^^^^
  File "/home/runner/work/docs.open223.info/docs.open223.info/.venv/lib/python3.12/site-packages/nbclient/client.py", line 806, in _async_poll_for_reply
    error_on_timeout_execute_reply = await self._async_handle_timeout(timeout, cell)
                                     ^^^^^^^^^^^^^^^^^^^^^^^^^^^^^^^^^^^^^^^^^^^^^^^
  File "/home/runner/work/docs.open223.info/docs.open223.info/.venv/lib/python3.12/site-packages/nbclient/client.py", line 856, in _async_handle_timeout
    raise CellTimeoutError.error_from_timeout_and_cell(
nbclient.exceptions.CellTimeoutError: A cell timed out while it was being executed, after 600 seconds.
The message was: Cell execution timed out.
Here is a preview of the cell contents:
-------------------
['import pyshacl', '', 'combined = model+s223', 'for _ in range(5):', '    pyshacl.validate(combined,']
...
["        inplace=True          # update the 'model' object with the inferred triples", '    )', '# remove the s223 graph from the model', 'model = combined - s223', 'print(f"The model now contains {len(model)} triples")']
-------------------

